
Error: Error: '/opt/log/gunicorn.error.log' isn't writable [FileNotFoundError(2, 'No such file or directory')]


Error: Error: '/opt/log/gunicorn.error.log' isn't writable [IsADirectoryError(21, 'Is a directory')]

usage: gunicorn [OPTIONS] [APP_MODULE]
gunicorn: error: unrecognized arguments: monit.wsgi:application
Internal Server Error: /
Traceback (most recent call last):
  File "/usr/local/lib/python3.5/dist-packages/django/core/handlers/exception.py", line 35, in inner
    response = get_response(request)
  File "/usr/local/lib/python3.5/dist-packages/django/core/handlers/base.py", line 128, in _get_response
    response = self.process_exception_by_middleware(e, request)
  File "/usr/local/lib/python3.5/dist-packages/django/core/handlers/base.py", line 126, in _get_response
    response = wrapped_callback(request, *callback_args, **callback_kwargs)
  File "/opt/monit/homepage/views.py", line 34, in index
    gas_device = gas_device[0]
  File "/usr/local/lib/python3.5/dist-packages/django/db/models/query.py", line 307, in __getitem__
    return qs._result_cache[0]
IndexError: list index out of range
Not Found: /user/index/
Internal Server Error: /index/
Traceback (most recent call last):
  File "/usr/local/lib/python3.5/dist-packages/django/core/handlers/exception.py", line 35, in inner
    response = get_response(request)
  File "/usr/local/lib/python3.5/dist-packages/django/core/handlers/base.py", line 128, in _get_response
    response = self.process_exception_by_middleware(e, request)
  File "/usr/local/lib/python3.5/dist-packages/django/core/handlers/base.py", line 126, in _get_response
    response = wrapped_callback(request, *callback_args, **callback_kwargs)
  File "/opt/monit/homepage/views.py", line 34, in index
    gas_device = gas_device[0]
  File "/usr/local/lib/python3.5/dist-packages/django/db/models/query.py", line 307, in __getitem__
    return qs._result_cache[0]
IndexError: list index out of range
Internal Server Error: /index/
Traceback (most recent call last):
  File "/usr/local/lib/python3.5/dist-packages/django/core/handlers/exception.py", line 35, in inner
    response = get_response(request)
  File "/usr/local/lib/python3.5/dist-packages/django/core/handlers/base.py", line 128, in _get_response
    response = self.process_exception_by_middleware(e, request)
  File "/usr/local/lib/python3.5/dist-packages/django/core/handlers/base.py", line 126, in _get_response
    response = wrapped_callback(request, *callback_args, **callback_kwargs)
  File "/opt/monit/homepage/views.py", line 34, in index
    gas_device = gas_device[0]
  File "/usr/local/lib/python3.5/dist-packages/django/db/models/query.py", line 307, in __getitem__
    return qs._result_cache[0]
IndexError: list index out of range
Internal Server Error: /
Traceback (most recent call last):
  File "/usr/local/lib/python3.5/dist-packages/django/core/handlers/exception.py", line 35, in inner
    response = get_response(request)
  File "/usr/local/lib/python3.5/dist-packages/django/core/handlers/base.py", line 128, in _get_response
    response = self.process_exception_by_middleware(e, request)
  File "/usr/local/lib/python3.5/dist-packages/django/core/handlers/base.py", line 126, in _get_response
    response = wrapped_callback(request, *callback_args, **callback_kwargs)
  File "/opt/monit/homepage/views.py", line 34, in index
    gas_device = gas_device[0]
  File "/usr/local/lib/python3.5/dist-packages/django/db/models/query.py", line 307, in __getitem__
    return qs._result_cache[0]
IndexError: list index out of range
Internal Server Error: /
Traceback (most recent call last):
  File "/usr/local/lib/python3.5/dist-packages/django/core/handlers/exception.py", line 35, in inner
    response = get_response(request)
  File "/usr/local/lib/python3.5/dist-packages/django/core/handlers/base.py", line 128, in _get_response
    response = self.process_exception_by_middleware(e, request)
  File "/usr/local/lib/python3.5/dist-packages/django/core/handlers/base.py", line 126, in _get_response
    response = wrapped_callback(request, *callback_args, **callback_kwargs)
  File "/opt/monit/homepage/views.py", line 34, in index
    gas_device = gas_device[0]
  File "/usr/local/lib/python3.5/dist-packages/django/db/models/query.py", line 307, in __getitem__
    return qs._result_cache[0]
IndexError: list index out of range
Internal Server Error: /
Traceback (most recent call last):
  File "/usr/local/lib/python3.5/dist-packages/django/core/handlers/exception.py", line 35, in inner
    response = get_response(request)
  File "/usr/local/lib/python3.5/dist-packages/django/core/handlers/base.py", line 128, in _get_response
    response = self.process_exception_by_middleware(e, request)
  File "/usr/local/lib/python3.5/dist-packages/django/core/handlers/base.py", line 126, in _get_response
    response = wrapped_callback(request, *callback_args, **callback_kwargs)
  File "/opt/monit/homepage/views.py", line 34, in index
    gas_device = gas_device[0]
  File "/usr/local/lib/python3.5/dist-packages/django/db/models/query.py", line 307, in __getitem__
    return qs._result_cache[0]
IndexError: list index out of range
Internal Server Error: /
Traceback (most recent call last):
  File "/usr/local/lib/python3.5/dist-packages/django/core/handlers/exception.py", line 35, in inner
    response = get_response(request)
  File "/usr/local/lib/python3.5/dist-packages/django/core/handlers/base.py", line 128, in _get_response
    response = self.process_exception_by_middleware(e, request)
  File "/usr/local/lib/python3.5/dist-packages/django/core/handlers/base.py", line 126, in _get_response
    response = wrapped_callback(request, *callback_args, **callback_kwargs)
  File "/opt/monit/homepage/views.py", line 34, in index
    gas_device = gas_device[0]
  File "/usr/local/lib/python3.5/dist-packages/django/db/models/query.py", line 307, in __getitem__
    return qs._result_cache[0]
IndexError: list index out of range
Internal Server Error: /
Traceback (most recent call last):
  File "/usr/local/lib/python3.5/dist-packages/django/core/handlers/exception.py", line 35, in inner
    response = get_response(request)
  File "/usr/local/lib/python3.5/dist-packages/django/core/handlers/base.py", line 128, in _get_response
    response = self.process_exception_by_middleware(e, request)
  File "/usr/local/lib/python3.5/dist-packages/django/core/handlers/base.py", line 126, in _get_response
    response = wrapped_callback(request, *callback_args, **callback_kwargs)
  File "/opt/monit/homepage/views.py", line 34, in index
    gas_device = gas_device[0]
  File "/usr/local/lib/python3.5/dist-packages/django/db/models/query.py", line 307, in __getitem__
    return qs._result_cache[0]
IndexError: list index out of range
Internal Server Error: /
Traceback (most recent call last):
  File "/usr/local/lib/python3.5/dist-packages/django/core/handlers/exception.py", line 35, in inner
    response = get_response(request)
  File "/usr/local/lib/python3.5/dist-packages/django/core/handlers/base.py", line 128, in _get_response
    response = self.process_exception_by_middleware(e, request)
  File "/usr/local/lib/python3.5/dist-packages/django/core/handlers/base.py", line 126, in _get_response
    response = wrapped_callback(request, *callback_args, **callback_kwargs)
  File "/opt/monit/homepage/views.py", line 34, in index
    gas_device = gas_device[0]
  File "/usr/local/lib/python3.5/dist-packages/django/db/models/query.py", line 307, in __getitem__
    return qs._result_cache[0]
IndexError: list index out of range
Internal Server Error: /
Traceback (most recent call last):
  File "/usr/local/lib/python3.5/dist-packages/django/core/handlers/exception.py", line 35, in inner
    response = get_response(request)
  File "/usr/local/lib/python3.5/dist-packages/django/core/handlers/base.py", line 128, in _get_response
    response = self.process_exception_by_middleware(e, request)
  File "/usr/local/lib/python3.5/dist-packages/django/core/handlers/base.py", line 126, in _get_response
    response = wrapped_callback(request, *callback_args, **callback_kwargs)
  File "/opt/monit/homepage/views.py", line 34, in index
    gas_device = gas_device[0]
  File "/usr/local/lib/python3.5/dist-packages/django/db/models/query.py", line 307, in __getitem__
    return qs._result_cache[0]
IndexError: list index out of range
Internal Server Error: /
Traceback (most recent call last):
  File "/usr/local/lib/python3.5/dist-packages/django/core/handlers/exception.py", line 35, in inner
    response = get_response(request)
  File "/usr/local/lib/python3.5/dist-packages/django/core/handlers/base.py", line 128, in _get_response
    response = self.process_exception_by_middleware(e, request)
  File "/usr/local/lib/python3.5/dist-packages/django/core/handlers/base.py", line 126, in _get_response
    response = wrapped_callback(request, *callback_args, **callback_kwargs)
  File "/opt/monit/homepage/views.py", line 34, in index
    gas_device = gas_device[0]
  File "/usr/local/lib/python3.5/dist-packages/django/db/models/query.py", line 307, in __getitem__
    return qs._result_cache[0]
IndexError: list index out of range
Internal Server Error: /
Traceback (most recent call last):
  File "/usr/local/lib/python3.5/dist-packages/django/core/handlers/exception.py", line 35, in inner
    response = get_response(request)
  File "/usr/local/lib/python3.5/dist-packages/django/core/handlers/base.py", line 128, in _get_response
    response = self.process_exception_by_middleware(e, request)
  File "/usr/local/lib/python3.5/dist-packages/django/core/handlers/base.py", line 126, in _get_response
    response = wrapped_callback(request, *callback_args, **callback_kwargs)
  File "/opt/monit/homepage/views.py", line 34, in index
    gas_device = gas_device[0]
  File "/usr/local/lib/python3.5/dist-packages/django/db/models/query.py", line 307, in __getitem__
    return qs._result_cache[0]
IndexError: list index out of range
Internal Server Error: /
Traceback (most recent call last):
  File "/usr/local/lib/python3.5/dist-packages/django/core/handlers/exception.py", line 35, in inner
    response = get_response(request)
  File "/usr/local/lib/python3.5/dist-packages/django/core/handlers/base.py", line 128, in _get_response
    response = self.process_exception_by_middleware(e, request)
  File "/usr/local/lib/python3.5/dist-packages/django/core/handlers/base.py", line 126, in _get_response
    response = wrapped_callback(request, *callback_args, **callback_kwargs)
  File "/opt/monit/homepage/views.py", line 34, in index
    gas_device = gas_device[0]
  File "/usr/local/lib/python3.5/dist-packages/django/db/models/query.py", line 307, in __getitem__
    return qs._result_cache[0]
IndexError: list index out of range
Internal Server Error: /
Traceback (most recent call last):
  File "/usr/local/lib/python3.5/dist-packages/django/core/handlers/exception.py", line 35, in inner
    response = get_response(request)
  File "/usr/local/lib/python3.5/dist-packages/django/core/handlers/base.py", line 128, in _get_response
    response = self.process_exception_by_middleware(e, request)
  File "/usr/local/lib/python3.5/dist-packages/django/core/handlers/base.py", line 126, in _get_response
    response = wrapped_callback(request, *callback_args, **callback_kwargs)
  File "/opt/monit/homepage/views.py", line 34, in index
    gas_device = gas_device[0]
  File "/usr/local/lib/python3.5/dist-packages/django/db/models/query.py", line 307, in __getitem__
    return qs._result_cache[0]
IndexError: list index out of range
Internal Server Error: /
Traceback (most recent call last):
  File "/usr/local/lib/python3.5/dist-packages/django/core/handlers/exception.py", line 35, in inner
    response = get_response(request)
  File "/usr/local/lib/python3.5/dist-packages/django/core/handlers/base.py", line 128, in _get_response
    response = self.process_exception_by_middleware(e, request)
  File "/usr/local/lib/python3.5/dist-packages/django/core/handlers/base.py", line 126, in _get_response
    response = wrapped_callback(request, *callback_args, **callback_kwargs)
  File "/opt/monit/homepage/views.py", line 34, in index
    gas_device = gas_device[0]
  File "/usr/local/lib/python3.5/dist-packages/django/db/models/query.py", line 307, in __getitem__
    return qs._result_cache[0]
IndexError: list index out of range
Not Found: /admin/assets/js/views/login.js
Internal Server Error: /
Traceback (most recent call last):
  File "/usr/local/lib/python3.5/dist-packages/django/core/handlers/exception.py", line 35, in inner
    response = get_response(request)
  File "/usr/local/lib/python3.5/dist-packages/django/core/handlers/base.py", line 128, in _get_response
    response = self.process_exception_by_middleware(e, request)
  File "/usr/local/lib/python3.5/dist-packages/django/core/handlers/base.py", line 126, in _get_response
    response = wrapped_callback(request, *callback_args, **callback_kwargs)
  File "/opt/monit/homepage/views.py", line 34, in index
    gas_device = gas_device[0]
  File "/usr/local/lib/python3.5/dist-packages/django/db/models/query.py", line 307, in __getitem__
    return qs._result_cache[0]
IndexError: list index out of range
Internal Server Error: /
Traceback (most recent call last):
  File "/usr/local/lib/python3.5/dist-packages/django/core/handlers/exception.py", line 35, in inner
    response = get_response(request)
  File "/usr/local/lib/python3.5/dist-packages/django/core/handlers/base.py", line 128, in _get_response
    response = self.process_exception_by_middleware(e, request)
  File "/usr/local/lib/python3.5/dist-packages/django/core/handlers/base.py", line 126, in _get_response
    response = wrapped_callback(request, *callback_args, **callback_kwargs)
  File "/opt/monit/homepage/views.py", line 34, in index
    gas_device = gas_device[0]
  File "/usr/local/lib/python3.5/dist-packages/django/db/models/query.py", line 307, in __getitem__
    return qs._result_cache[0]
IndexError: list index out of range
Internal Server Error: /
Traceback (most recent call last):
  File "/usr/local/lib/python3.5/dist-packages/django/core/handlers/exception.py", line 35, in inner
    response = get_response(request)
  File "/usr/local/lib/python3.5/dist-packages/django/core/handlers/base.py", line 128, in _get_response
    response = self.process_exception_by_middleware(e, request)
  File "/usr/local/lib/python3.5/dist-packages/django/core/handlers/base.py", line 126, in _get_response
    response = wrapped_callback(request, *callback_args, **callback_kwargs)
  File "/opt/monit/homepage/views.py", line 34, in index
    gas_device = gas_device[0]
  File "/usr/local/lib/python3.5/dist-packages/django/db/models/query.py", line 307, in __getitem__
    return qs._result_cache[0]
IndexError: list index out of range
Not Found: /user/register
Internal Server Error: /
Traceback (most recent call last):
  File "/usr/local/lib/python3.5/dist-packages/django/core/handlers/exception.py", line 35, in inner
    response = get_response(request)
  File "/usr/local/lib/python3.5/dist-packages/django/core/handlers/base.py", line 128, in _get_response
    response = self.process_exception_by_middleware(e, request)
  File "/usr/local/lib/python3.5/dist-packages/django/core/handlers/base.py", line 126, in _get_response
    response = wrapped_callback(request, *callback_args, **callback_kwargs)
  File "/opt/monit/homepage/views.py", line 34, in index
    gas_device = gas_device[0]
  File "/usr/local/lib/python3.5/dist-packages/django/db/models/query.py", line 307, in __getitem__
    return qs._result_cache[0]
IndexError: list index out of range
Internal Server Error: /
Traceback (most recent call last):
  File "/usr/local/lib/python3.5/dist-packages/django/core/handlers/exception.py", line 35, in inner
    response = get_response(request)
  File "/usr/local/lib/python3.5/dist-packages/django/core/handlers/base.py", line 128, in _get_response
    response = self.process_exception_by_middleware(e, request)
  File "/usr/local/lib/python3.5/dist-packages/django/core/handlers/base.py", line 126, in _get_response
    response = wrapped_callback(request, *callback_args, **callback_kwargs)
  File "/opt/monit/homepage/views.py", line 34, in index
    gas_device = gas_device[0]
  File "/usr/local/lib/python3.5/dist-packages/django/db/models/query.py", line 307, in __getitem__
    return qs._result_cache[0]
IndexError: list index out of range
Internal Server Error: /
Traceback (most recent call last):
  File "/usr/local/lib/python3.5/dist-packages/django/core/handlers/exception.py", line 35, in inner
    response = get_response(request)
  File "/usr/local/lib/python3.5/dist-packages/django/core/handlers/base.py", line 128, in _get_response
    response = self.process_exception_by_middleware(e, request)
  File "/usr/local/lib/python3.5/dist-packages/django/core/handlers/base.py", line 126, in _get_response
    response = wrapped_callback(request, *callback_args, **callback_kwargs)
  File "/opt/monit/homepage/views.py", line 34, in index
    gas_device = gas_device[0]
  File "/usr/local/lib/python3.5/dist-packages/django/db/models/query.py", line 307, in __getitem__
    return qs._result_cache[0]
IndexError: list index out of range
Internal Server Error: /
Traceback (most recent call last):
  File "/usr/local/lib/python3.5/dist-packages/django/core/handlers/exception.py", line 35, in inner
    response = get_response(request)
  File "/usr/local/lib/python3.5/dist-packages/django/core/handlers/base.py", line 128, in _get_response
    response = self.process_exception_by_middleware(e, request)
  File "/usr/local/lib/python3.5/dist-packages/django/core/handlers/base.py", line 126, in _get_response
    response = wrapped_callback(request, *callback_args, **callback_kwargs)
  File "/opt/monit/homepage/views.py", line 34, in index
    gas_device = gas_device[0]
  File "/usr/local/lib/python3.5/dist-packages/django/db/models/query.py", line 307, in __getitem__
    return qs._result_cache[0]
IndexError: list index out of range
Not Found: /webdav/
Not Found: /help.php
Not Found: /java.php
Not Found: /_query.php
Not Found: /test.php
Not Found: /db_cts.php
Not Found: /db_pma.php
Not Found: /help-e.php
Not Found: /license.php
Not Found: /log.php
Not Found: /pmd_online.php
Not Found: /x.php
Not Found: /shell.php
Not Found: /htdocs.php
Not Found: /desktop.ini.php
Not Found: /z.php
Not Found: /lala.php
Not Found: /lala-dpr.php
Not Found: /wpo.php
Not Found: /text.php
Not Found: /wp-config.php
Not Found: /muhstik.php
Not Found: /muhstik2.php
Not Found: /muhstiks.php
Not Found: /muhstik-dpr.php
Not Found: /lol.php
Not Found: /uploader.php
Not Found: /cmd.php
Not Found: /cmx.php
Not Found: /cmv.php
Not Found: /cmdd.php
Not Found: /knal.php
Not Found: /shell.php
Not Found: /appserv.php
Not Found: /scripts/setup.php
Not Found: /phpmyadmin/scripts/setup.php
Not Found: /phpMyAdmin/scripts/setup.php
Not Found: /phpmyadmin/scripts/db___.init.php
Not Found: /phpMyAdmin/scripts/db___.init.php
Not Found: /plugins/weathermap/editor.php
Not Found: /cacti/plugins/weathermap/editor.php
Not Found: /wuwu11.php
Not Found: /xw.php
Not Found: /xw1.php
Not Found: /9678.php
Not Found: /wc.php
Not Found: /xx.php
Not Found: /s.php
Not Found: /w.php
Not Found: /sheep.php
Not Found: /qaq.php
Not Found: /db.init.php
Not Found: /db_session.init.php
Not Found: /db__.init.php
Not Found: /wp-admins.php
Not Found: /m.php
Not Found: /db_dataml.php
Not Found: /db_desql.php
Not Found: /mx.php
Not Found: /wshell.php
Not Found: /xshell.php
Not Found: /qq.php
Not Found: /lindex.php
Not Found: /phpstudy.php
Not Found: /phpStudy.php
Not Found: /weixiao.php
Not Found: /feixiang.php
Not Found: /ak47.php
Not Found: /ak48.php
Not Found: /xiao.php
Not Found: /yao.php
Not Found: /defect.php
Not Found: /webslee.php
Not Found: /q.php
Not Found: /pe.php
Not Found: /cainiao.php
Not Found: /zuoshou.php
Not Found: /zuo.php
Not Found: /aotu.php
Not Found: /cmd.php
Not Found: /bak.php
Not Found: /system.php
Not Found: /l6.php
Not Found: /l7.php
Not Found: /l8.php
Not Found: /q.php
Not Found: /56.php
Not Found: /mz.php
Not Found: /xx.php
Not Found: /yumo.php
Not Found: /min.php
Not Found: /wan.php
Not Found: /wanan.php
Not Found: /ssaa.php
Not Found: /qq.php
Not Found: /aw.php
Not Found: /12.php
Not Found: /hh.php
Not Found: /ak.php
Not Found: /ip.php
Not Found: /infoo.php
Not Found: /qq.php
Not Found: /qwe.php
Not Found: /1213.php
Not Found: /post.php
Not Found: /h1.php
Not Found: /test.php
Not Found: /3.php
Not Found: /phpinfi.php
Not Found: /aaaa.php
Not Found: /9510.php
Not Found: /python.php
Not Found: /default.php
Not Found: /sean.php
Not Found: /app.php
Not Found: /help.php
Not Found: /tiandi.php
Not Found: /miao.php
Not Found: /xz.php
Not Found: /linuxse.php
Not Found: /zuoindex.php
Not Found: /tomcat.php
Not Found: /ceshi.php
Not Found: /1hou.php
Not Found: /ou2.php
Not Found: /zuos.php
Not Found: /zuoss.php
Not Found: /zuoshss.php
Not Found: /boots.php
Not Found: /she.php
Not Found: /s.php
Not Found: /qw.php
Not Found: /test.php
Not Found: /caonma.php
Not Found: /ss.php
Not Found: /wcp.php
Not Found: /u.php
Not Found: /uuu.php
Not Found: /sss.php
Not Found: /1.php
Not Found: /2.php
Not Found: /core.php
Not Found: /qaz.php
Not Found: /sha.php
Not Found: /ppx.php
Not Found: /1.php
Not Found: /confg.php
Not Found: /conf1g.php
Not Found: /confg.php
Not Found: /confg.php
Not Found: /ver.php
Not Found: /hack.php
Not Found: /qa.php
Not Found: /Ss.php
Not Found: /xxx.php
Not Found: /92.php
Not Found: /z.php
Not Found: /x.php
Not Found: /dexgp.php
Not Found: /nuoxi.php
Not Found: /godkey.php
Not Found: /okokok.php
Not Found: /erwa.php
Not Found: /pma.php
Not Found: /ruyi.php
Not Found: /51314.php
Not Found: /5201314.php
Not Found: /fusheng.php
Not Found: /general.php
Not Found: /repeat.php
Not Found: /ldw.php
Not Found: /api.php
Not Found: /s1.php
Not Found: /xiaodai.php
Not Found: /hello.php
Not Found: /xp.php
Not Found: /2.php
Not Found: /p.php
Not Found: /1.php
Not Found: /a.php
Not Found: /m.php
Not Found: /conf.php
Not Found: /123.php
Not Found: /HX.php
Not Found: /diy.php
Not Found: /666.php
Not Found: /777.php
Not Found: /qwq.php
Not Found: /.php
Not Found: /infos.php
Not Found: /x.php
Not Found: /htfr.php
Not Found: /zzk.php
Not Found: /xiaoma.php
Not Found: /xiaomae.php
Not Found: /xiaomar.php
Not Found: /qq.php
Not Found: /data.php
Not Found: /log.php
Not Found: /fack.php
Not Found: /angge.php
Not Found: /index.php
Not Found: /phpMyAdmin/index.php
Not Found: /pmd/index.php
Not Found: /pma/index.php
Not Found: /PMA/index.php
Not Found: /PMA2/index.php
Not Found: /pmamy/index.php
Not Found: /pmamy2/index.php
Not Found: /mysql/index.php
Not Found: /admin/index.php
Not Found: /db/index.php
Not Found: /dbadmin/index.php
Not Found: /web/phpMyAdmin/index.php
Not Found: /admin/pma/index.php
Not Found: /admin/PMA/index.php
Not Found: /admin/mysql/index.php
Not Found: /admin/mysql2/index.php
Not Found: /admin/phpmyadmin/index.php
Not Found: /admin/phpMyAdmin/index.php
Not Found: /admin/phpmyadmin2/index.php
Not Found: /mysqladmin/index.php
Not Found: /mysql-admin/index.php
Not Found: /phpadmin/index.php
Not Found: /phpAdmin/index.php
Not Found: /phpmyadmin0/index.php
Not Found: /phpmyadmin1/index.php
Not Found: /phpmyadmin2/index.php
Not Found: /phpMyAdmin-4.4.0/index.php
Not Found: /myadmin/index.php
Not Found: /myadmin2/index.php
Not Found: /xampp/phpmyadmin/index.php
Not Found: /phpMyadmin_bak/index.php
Not Found: /www/phpMyAdmin/index.php
Not Found: /tools/phpMyAdmin/index.php
Not Found: /phpmyadmin-old/index.php
Not Found: /phpMyAdminold/index.php
Not Found: /phpMyAdmin.old/index.php
Not Found: /pma-old/index.php
Not Found: /claroline/phpMyAdmin/index.php
Not Found: /typo3/phpmyadmin/index.php
Not Found: /phpma/index.php
Not Found: /phpmyadmin/phpmyadmin/index.php
Not Found: /phpMyAdmin/phpMyAdmin/index.php
Not Found: /phpMyAbmin/index.php
Not Found: /phpMyAdmin__/index.php
Not Found: /phpMyAdmin+++---/index.php
Not Found: /v/index.php
Not Found: /phpmyadm1n/index.php
Not Found: /phpMyAdm1n/index.php
Not Found: /shaAdmin/index.php
Not Found: /phpMyadmi/index.php
Not Found: /phpMyAdmion/index.php
Not Found: /MyAdmin/index.php
Not Found: /phpMyAdmin1/index.php
Internal Server Error: /
Traceback (most recent call last):
  File "/usr/local/lib/python3.5/dist-packages/django/core/handlers/exception.py", line 35, in inner
    response = get_response(request)
  File "/usr/local/lib/python3.5/dist-packages/django/core/handlers/base.py", line 128, in _get_response
    response = self.process_exception_by_middleware(e, request)
  File "/usr/local/lib/python3.5/dist-packages/django/core/handlers/base.py", line 126, in _get_response
    response = wrapped_callback(request, *callback_args, **callback_kwargs)
  File "/opt/monit/homepage/views.py", line 34, in index
    gas_device = gas_device[0]
  File "/usr/local/lib/python3.5/dist-packages/django/db/models/query.py", line 307, in __getitem__
    return qs._result_cache[0]
IndexError: list index out of range
Not Found: /images/json
Internal Server Error: /
Traceback (most recent call last):
  File "/usr/local/lib/python3.5/dist-packages/django/core/handlers/exception.py", line 35, in inner
    response = get_response(request)
  File "/usr/local/lib/python3.5/dist-packages/django/core/handlers/base.py", line 128, in _get_response
    response = self.process_exception_by_middleware(e, request)
  File "/usr/local/lib/python3.5/dist-packages/django/core/handlers/base.py", line 126, in _get_response
    response = wrapped_callback(request, *callback_args, **callback_kwargs)
  File "/opt/monit/homepage/views.py", line 34, in index
    gas_device = gas_device[0]
  File "/usr/local/lib/python3.5/dist-packages/django/db/models/query.py", line 307, in __getitem__
    return qs._result_cache[0]
IndexError: list index out of range
Internal Server Error: /
Traceback (most recent call last):
  File "/usr/local/lib/python3.5/dist-packages/django/core/handlers/exception.py", line 35, in inner
    response = get_response(request)
  File "/usr/local/lib/python3.5/dist-packages/django/core/handlers/base.py", line 128, in _get_response
    response = self.process_exception_by_middleware(e, request)
  File "/usr/local/lib/python3.5/dist-packages/django/core/handlers/base.py", line 126, in _get_response
    response = wrapped_callback(request, *callback_args, **callback_kwargs)
  File "/opt/monit/homepage/views.py", line 34, in index
    gas_device = gas_device[0]
  File "/usr/local/lib/python3.5/dist-packages/django/db/models/query.py", line 307, in __getitem__
    return qs._result_cache[0]
IndexError: list index out of range
Internal Server Error: /
Traceback (most recent call last):
  File "/usr/local/lib/python3.5/dist-packages/django/core/handlers/exception.py", line 35, in inner
    response = get_response(request)
  File "/usr/local/lib/python3.5/dist-packages/django/core/handlers/base.py", line 128, in _get_response
    response = self.process_exception_by_middleware(e, request)
  File "/usr/local/lib/python3.5/dist-packages/django/core/handlers/base.py", line 126, in _get_response
    response = wrapped_callback(request, *callback_args, **callback_kwargs)
  File "/opt/monit/homepage/views.py", line 34, in index
    gas_device = gas_device[0]
  File "/usr/local/lib/python3.5/dist-packages/django/db/models/query.py", line 307, in __getitem__
    return qs._result_cache[0]
IndexError: list index out of range
Internal Server Error: /
Traceback (most recent call last):
  File "/usr/local/lib/python3.5/dist-packages/django/core/handlers/exception.py", line 35, in inner
    response = get_response(request)
  File "/usr/local/lib/python3.5/dist-packages/django/core/handlers/base.py", line 128, in _get_response
    response = self.process_exception_by_middleware(e, request)
  File "/usr/local/lib/python3.5/dist-packages/django/core/handlers/base.py", line 126, in _get_response
    response = wrapped_callback(request, *callback_args, **callback_kwargs)
  File "/opt/monit/homepage/views.py", line 34, in index
    gas_device = gas_device[0]
  File "/usr/local/lib/python3.5/dist-packages/django/db/models/query.py", line 307, in __getitem__
    return qs._result_cache[0]
IndexError: list index out of range
Not Found: /index.action
Not Found: /prov
Not Found: /provisioning
Internal Server Error: /
Traceback (most recent call last):
  File "/usr/local/lib/python3.5/dist-packages/django/core/handlers/exception.py", line 35, in inner
    response = get_response(request)
  File "/usr/local/lib/python3.5/dist-packages/django/core/handlers/base.py", line 128, in _get_response
    response = self.process_exception_by_middleware(e, request)
  File "/usr/local/lib/python3.5/dist-packages/django/core/handlers/base.py", line 126, in _get_response
    response = wrapped_callback(request, *callback_args, **callback_kwargs)
  File "/opt/monit/homepage/views.py", line 34, in index
    gas_device = gas_device[0]
  File "/usr/local/lib/python3.5/dist-packages/django/db/models/query.py", line 307, in __getitem__
    return qs._result_cache[0]
IndexError: list index out of range
Internal Server Error: /
Traceback (most recent call last):
  File "/usr/local/lib/python3.5/dist-packages/django/core/handlers/exception.py", line 35, in inner
    response = get_response(request)
  File "/usr/local/lib/python3.5/dist-packages/django/core/handlers/base.py", line 128, in _get_response
    response = self.process_exception_by_middleware(e, request)
  File "/usr/local/lib/python3.5/dist-packages/django/core/handlers/base.py", line 126, in _get_response
    response = wrapped_callback(request, *callback_args, **callback_kwargs)
  File "/opt/monit/homepage/views.py", line 34, in index
    gas_device = gas_device[0]
  File "/usr/local/lib/python3.5/dist-packages/django/db/models/query.py", line 307, in __getitem__
    return qs._result_cache[0]
IndexError: list index out of range
Not Found: /favicon.ico
